2023-12-25 08:32:57,990 INFO    StreamThr :2017346 [internal.py:wandb_internal():89] W&B internal server running at pid: 2017346, started at: 2023-12-25 08:32:57.989978
2023-12-25 08:32:57,992 DEBUG   HandlerThread:2017346 [handler.py:handle_request():146] handle_request: status
2023-12-25 08:32:57,993 INFO    WriterThread:2017346 [datastore.py:open_for_write():85] open: /alpha/overcooked_rl/algorithms/baselines/wandb/run-20231225_083257-84x3ne8d/run-84x3ne8d.wandb
2023-12-25 08:32:57,996 DEBUG   SenderThread:2017346 [sender.py:send():382] send: header
2023-12-25 08:32:58,007 DEBUG   SenderThread:2017346 [sender.py:send():382] send: run
2023-12-25 08:33:03,008 DEBUG   HandlerThread:2017346 [handler.py:handle_request():146] handle_request: keepalive
2023-12-25 08:33:08,010 DEBUG   HandlerThread:2017346 [handler.py:handle_request():146] handle_request: keepalive
2023-12-25 08:33:13,011 DEBUG   HandlerThread:2017346 [handler.py:handle_request():146] handle_request: keepalive
2023-12-25 08:33:18,013 DEBUG   HandlerThread:2017346 [handler.py:handle_request():146] handle_request: keepalive
2023-12-25 08:33:23,014 DEBUG   HandlerThread:2017346 [handler.py:handle_request():146] handle_request: keepalive
2023-12-25 08:33:28,016 DEBUG   HandlerThread:2017346 [handler.py:handle_request():146] handle_request: keepalive
2023-12-25 08:33:33,017 DEBUG   HandlerThread:2017346 [handler.py:handle_request():146] handle_request: keepalive
2023-12-25 08:33:38,019 DEBUG   HandlerThread:2017346 [handler.py:handle_request():146] handle_request: keepalive
2023-12-25 08:33:43,020 DEBUG   HandlerThread:2017346 [handler.py:handle_request():146] handle_request: keepalive
2023-12-25 08:33:48,022 DEBUG   HandlerThread:2017346 [handler.py:handle_request():146] handle_request: keepalive
2023-12-25 08:33:53,023 DEBUG   HandlerThread:2017346 [handler.py:handle_request():146] handle_request: keepalive
2023-12-25 08:33:54,623 INFO    SenderThread:2017346 [retry.py:__call__():172] Retry attempt failed:
Traceback (most recent call last):
  File "/home/wanghm/anaconda3/envs/overcooked_ai/lib/python3.7/site-packages/urllib3/connectionpool.py", line 677, in urlopen
    chunked=chunked,
  File "/home/wanghm/anaconda3/envs/overcooked_ai/lib/python3.7/site-packages/urllib3/connectionpool.py", line 381, in _make_request
    self._validate_conn(conn)
  File "/home/wanghm/anaconda3/envs/overcooked_ai/lib/python3.7/site-packages/urllib3/connectionpool.py", line 978, in _validate_conn
    conn.connect()
  File "/home/wanghm/anaconda3/envs/overcooked_ai/lib/python3.7/site-packages/urllib3/connection.py", line 371, in connect
    ssl_context=context,
  File "/home/wanghm/anaconda3/envs/overcooked_ai/lib/python3.7/site-packages/urllib3/util/ssl_.py", line 386, in ssl_wrap_socket
    return context.wrap_socket(sock, server_hostname=server_hostname)
  File "/home/wanghm/anaconda3/envs/overcooked_ai/lib/python3.7/ssl.py", line 423, in wrap_socket
    session=session
  File "/home/wanghm/anaconda3/envs/overcooked_ai/lib/python3.7/ssl.py", line 870, in _create
    self.do_handshake()
  File "/home/wanghm/anaconda3/envs/overcooked_ai/lib/python3.7/ssl.py", line 1139, in do_handshake
    self._sslobj.do_handshake()
ssl.SSLError: [SSL: KRB5_S_TKT_NYV] unexpected eof while reading (_ssl.c:1091)

During handling of the above exception, another exception occurred:

Traceback (most recent call last):
  File "/home/wanghm/anaconda3/envs/overcooked_ai/lib/python3.7/site-packages/requests/adapters.py", line 449, in send
    timeout=timeout
  File "/home/wanghm/anaconda3/envs/overcooked_ai/lib/python3.7/site-packages/urllib3/connectionpool.py", line 727, in urlopen
    method, url, error=e, _pool=self, _stacktrace=sys.exc_info()[2]
  File "/home/wanghm/anaconda3/envs/overcooked_ai/lib/python3.7/site-packages/urllib3/util/retry.py", line 446, in increment
    raise MaxRetryError(_pool, url, error or ResponseError(cause))
urllib3.exceptions.MaxRetryError: HTTPSConnectionPool(host='api.wandb.ai', port=443): Max retries exceeded with url: /graphql (Caused by SSLError(SSLError(1, '[SSL: KRB5_S_TKT_NYV] unexpected eof while reading (_ssl.c:1091)')))

During handling of the above exception, another exception occurred:

Traceback (most recent call last):
  File "/home/wanghm/anaconda3/envs/overcooked_ai/lib/python3.7/site-packages/wandb/sdk/lib/retry.py", line 131, in __call__
    result = self._call_fn(*args, **kwargs)
  File "/home/wanghm/anaconda3/envs/overcooked_ai/lib/python3.7/site-packages/wandb/sdk/internal/internal_api.py", line 369, in execute
    return self.client.execute(*args, **kwargs)  # type: ignore
  File "/home/wanghm/anaconda3/envs/overcooked_ai/lib/python3.7/site-packages/wandb/vendor/gql-0.2.0/wandb_gql/client.py", line 52, in execute
    result = self._get_result(document, *args, **kwargs)
  File "/home/wanghm/anaconda3/envs/overcooked_ai/lib/python3.7/site-packages/wandb/vendor/gql-0.2.0/wandb_gql/client.py", line 60, in _get_result
    return self.transport.execute(document, *args, **kwargs)
  File "/home/wanghm/anaconda3/envs/overcooked_ai/lib/python3.7/site-packages/wandb/sdk/lib/gql_request.py", line 58, in execute
    request = self.session.post(self.url, **post_args)
  File "/home/wanghm/anaconda3/envs/overcooked_ai/lib/python3.7/site-packages/requests/sessions.py", line 578, in post
    return self.request('POST', url, data=data, json=json, **kwargs)
  File "/home/wanghm/anaconda3/envs/overcooked_ai/lib/python3.7/site-packages/requests/sessions.py", line 530, in request
    resp = self.send(prep, **send_kwargs)
  File "/home/wanghm/anaconda3/envs/overcooked_ai/lib/python3.7/site-packages/requests/sessions.py", line 643, in send
    r = adapter.send(request, **kwargs)
  File "/home/wanghm/anaconda3/envs/overcooked_ai/lib/python3.7/site-packages/requests/adapters.py", line 514, in send
    raise SSLError(e, request=request)
requests.exceptions.SSLError: HTTPSConnectionPool(host='api.wandb.ai', port=443): Max retries exceeded with url: /graphql (Caused by SSLError(SSLError(1, '[SSL: KRB5_S_TKT_NYV] unexpected eof while reading (_ssl.c:1091)')))
2023-12-25 08:33:58,025 DEBUG   HandlerThread:2017346 [handler.py:handle_request():146] handle_request: keepalive
2023-12-25 08:34:03,026 DEBUG   HandlerThread:2017346 [handler.py:handle_request():146] handle_request: keepalive
2023-12-25 08:34:08,028 DEBUG   HandlerThread:2017346 [handler.py:handle_request():146] handle_request: keepalive
2023-12-25 08:34:09,519 INFO    SenderThread:2017346 [dir_watcher.py:__init__():211] watching files in: /alpha/overcooked_rl/algorithms/baselines/wandb/run-20231225_083257-84x3ne8d/files
2023-12-25 08:34:09,519 INFO    SenderThread:2017346 [sender.py:_start_run_threads():1139] run started: 84x3ne8d with start time 1703464377.989742
2023-12-25 08:34:09,520 DEBUG   HandlerThread:2017346 [handler.py:handle_request():146] handle_request: status_report
2023-12-25 08:34:09,525 DEBUG   HandlerThread:2017346 [handler.py:handle_request():146] handle_request: check_version
2023-12-25 08:34:09,525 DEBUG   SenderThread:2017346 [sender.py:send_request():409] send_request: check_version
2023-12-25 08:34:09,799 DEBUG   HandlerThread:2017346 [handler.py:handle_request():146] handle_request: run_start
2023-12-25 08:34:09,806 DEBUG   HandlerThread:2017346 [system_info.py:__init__():32] System info init
2023-12-25 08:34:09,806 DEBUG   HandlerThread:2017346 [system_info.py:__init__():47] System info init done
2023-12-25 08:34:09,806 INFO    HandlerThread:2017346 [system_monitor.py:start():194] Starting system monitor
2023-12-25 08:34:09,806 INFO    SystemMonitor:2017346 [system_monitor.py:_start():158] Starting system asset monitoring threads
2023-12-25 08:34:09,806 INFO    HandlerThread:2017346 [system_monitor.py:probe():214] Collecting system info
2023-12-25 08:34:09,807 INFO    SystemMonitor:2017346 [interfaces.py:start():190] Started cpu monitoring
2023-12-25 08:34:09,807 INFO    SystemMonitor:2017346 [interfaces.py:start():190] Started disk monitoring
2023-12-25 08:34:09,808 INFO    SystemMonitor:2017346 [interfaces.py:start():190] Started gpu monitoring
2023-12-25 08:34:09,809 INFO    SystemMonitor:2017346 [interfaces.py:start():190] Started memory monitoring
2023-12-25 08:34:09,809 INFO    SystemMonitor:2017346 [interfaces.py:start():190] Started network monitoring
2023-12-25 08:34:09,819 DEBUG   HandlerThread:2017346 [system_info.py:probe():196] Probing system
2023-12-25 08:34:09,826 DEBUG   HandlerThread:2017346 [system_info.py:_probe_git():181] Probing git
2023-12-25 08:34:09,841 DEBUG   HandlerThread:2017346 [system_info.py:_probe_git():189] Probing git done
2023-12-25 08:34:09,841 DEBUG   HandlerThread:2017346 [system_info.py:probe():244] Probing system done
2023-12-25 08:34:09,841 DEBUG   HandlerThread:2017346 [system_monitor.py:probe():223] {'os': 'Linux-6.2.0-26-generic-x86_64-with-debian-bookworm-sid', 'python': '3.7.12', 'heartbeatAt': '2023-12-25T00:34:09.819951', 'startedAt': '2023-12-25T00:32:57.986219', 'docker': None, 'cuda': None, 'args': (), 'state': 'running', 'program': '/alpha/overcooked_rl/algorithms/baselines/sp_ppo.py', 'codePathLocal': 'sp_ppo.py', 'codePath': 'algorithms/baselines/sp_ppo.py', 'git': {'remote': 'git@github.com:AlexWanghaoming/overcooked_rl.git', 'commit': '4bae474f798d5eecf1ba22b019e08091187b53ea'}, 'email': '568019240@qq.com', 'root': '/alpha/overcooked_rl', 'host': 'wanghm', 'username': 'wanghm', 'executable': '/home/wanghm/anaconda3/envs/overcooked_ai/bin/python', 'cpu_count': 8, 'cpu_count_logical': 16, 'cpu_freq': {'current': 4747.655187500001, 'min': 800.0, 'max': 5150.0}, 'cpu_freq_per_core': [{'current': 4775.82, 'min': 800.0, 'max': 5100.0}, {'current': 4852.523, 'min': 800.0, 'max': 5100.0}, {'current': 4801.621, 'min': 800.0, 'max': 5100.0}, {'current': 4801.326, 'min': 800.0, 'max': 5100.0}, {'current': 4793.679, 'min': 800.0, 'max': 5300.0}, {'current': 4798.75, 'min': 800.0, 'max': 5300.0}, {'current': 4800.37, 'min': 800.0, 'max': 5100.0}, {'current': 4532.154, 'min': 800.0, 'max': 5100.0}, {'current': 4794.6, 'min': 800.0, 'max': 5100.0}, {'current': 4762.059, 'min': 800.0, 'max': 5100.0}, {'current': 4769.529, 'min': 800.0, 'max': 5100.0}, {'current': 4801.438, 'min': 800.0, 'max': 5100.0}, {'current': 3500.0, 'min': 800.0, 'max': 5300.0}, {'current': 4800.0, 'min': 800.0, 'max': 5300.0}, {'current': 4726.475, 'min': 800.0, 'max': 5100.0}, {'current': 4689.536, 'min': 800.0, 'max': 5100.0}], 'disk': {'/': {'total': 1832.2072448730469, 'used': 197.80001068115234}}, 'gpu': 'NVIDIA GeForce RTX 3080', 'gpu_count': 1, 'gpu_devices': [{'name': 'NVIDIA GeForce RTX 3080', 'memory_total': 10737418240}], 'memory': {'total': 31.16317367553711}}
2023-12-25 08:34:09,841 INFO    HandlerThread:2017346 [system_monitor.py:probe():224] Finished collecting system info
2023-12-25 08:34:09,841 INFO    HandlerThread:2017346 [system_monitor.py:probe():227] Publishing system info
2023-12-25 08:34:09,841 DEBUG   HandlerThread:2017346 [system_info.py:_save_pip():53] Saving list of pip packages installed into the current environment
2023-12-25 08:34:09,842 DEBUG   HandlerThread:2017346 [system_info.py:_save_pip():68] Saving pip packages done
2023-12-25 08:34:09,842 DEBUG   HandlerThread:2017346 [system_info.py:_save_conda():76] Saving list of conda packages installed into the current environment
2023-12-25 08:34:10,520 INFO    Thread-12 :2017346 [dir_watcher.py:_on_file_created():271] file/dir created: /alpha/overcooked_rl/algorithms/baselines/wandb/run-20231225_083257-84x3ne8d/files/conda-environment.yaml
2023-12-25 08:34:10,520 INFO    Thread-12 :2017346 [dir_watcher.py:_on_file_created():271] file/dir created: /alpha/overcooked_rl/algorithms/baselines/wandb/run-20231225_083257-84x3ne8d/files/requirements.txt
2023-12-25 08:34:12,521 INFO    Thread-12 :2017346 [dir_watcher.py:_on_file_modified():288] file/dir modified: /alpha/overcooked_rl/algorithms/baselines/wandb/run-20231225_083257-84x3ne8d/files/conda-environment.yaml
2023-12-25 08:34:12,544 DEBUG   HandlerThread:2017346 [system_info.py:_save_conda():87] Saving conda packages done
2023-12-25 08:34:12,545 INFO    HandlerThread:2017346 [system_monitor.py:probe():229] Finished publishing system info
2023-12-25 08:34:12,550 DEBUG   SenderThread:2017346 [sender.py:send():382] send: files
2023-12-25 08:34:12,550 INFO    SenderThread:2017346 [sender.py:_save_file():1392] saving file wandb-metadata.json with policy now
2023-12-25 08:34:12,554 DEBUG   HandlerThread:2017346 [handler.py:handle_request():146] handle_request: stop_status
2023-12-25 08:34:12,555 DEBUG   SenderThread:2017346 [sender.py:send_request():409] send_request: stop_status
2023-12-25 08:34:12,557 DEBUG   HandlerThread:2017346 [handler.py:handle_request():146] handle_request: internal_messages
2023-12-25 08:34:13,521 INFO    Thread-12 :2017346 [dir_watcher.py:_on_file_created():271] file/dir created: /alpha/overcooked_rl/algorithms/baselines/wandb/run-20231225_083257-84x3ne8d/files/wandb-metadata.json
2023-12-25 08:34:13,558 DEBUG   HandlerThread:2017346 [handler.py:handle_request():146] handle_request: poll_exit
2023-12-25 08:34:18,560 DEBUG   HandlerThread:2017346 [handler.py:handle_request():146] handle_request: keepalive
2023-12-25 08:34:23,561 DEBUG   HandlerThread:2017346 [handler.py:handle_request():146] handle_request: keepalive
2023-12-25 08:34:28,563 DEBUG   HandlerThread:2017346 [handler.py:handle_request():146] handle_request: keepalive
2023-12-25 08:34:32,792 INFO    wandb-upload_0:2017346 [upload_job.py:push():131] Uploaded file /tmp/tmphpae70h5wandb/vd2sxani-wandb-metadata.json
2023-12-25 08:34:33,564 DEBUG   HandlerThread:2017346 [handler.py:handle_request():146] handle_request: keepalive
2023-12-25 08:34:37,822 INFO    cpu       :2017346 [interfaces.py:monitor():140] Process cpu has exited.
2023-12-25 08:34:37,823 DEBUG   SystemMonitor:2017346 [system_monitor.py:_start():172] Starting system metrics aggregation loop
2023-12-25 08:34:37,823 DEBUG   SystemMonitor:2017346 [system_monitor.py:_start():179] Finished system metrics aggregation loop
2023-12-25 08:34:37,823 DEBUG   SystemMonitor:2017346 [system_monitor.py:_start():183] Publishing last batch of metrics
2023-12-25 08:34:37,824 INFO    memory    :2017346 [interfaces.py:monitor():140] Process proc.memory.rssMB has exited.
2023-12-25 08:34:43,086 WARNING StreamThr :2017346 [internal.py:is_dead():415] Internal process exiting, parent pid 2017312 disappeared
2023-12-25 08:34:43,087 ERROR   StreamThr :2017346 [internal.py:wandb_internal():152] Internal process shutdown.
2023-12-25 08:34:43,825 INFO    HandlerThread:2017346 [handler.py:finish():866] shutting down handler
2023-12-25 08:34:43,825 INFO    WriterThread:2017346 [datastore.py:close():294] close: /alpha/overcooked_rl/algorithms/baselines/wandb/run-20231225_083257-84x3ne8d/run-84x3ne8d.wandb
2023-12-25 08:34:43,825 INFO    HandlerThread:2017346 [system_monitor.py:finish():203] Stopping system monitor
2023-12-25 08:34:43,825 INFO    HandlerThread:2017346 [interfaces.py:finish():202] Joined cpu monitor
2023-12-25 08:34:43,825 INFO    HandlerThread:2017346 [interfaces.py:finish():202] Joined disk monitor
2023-12-25 08:34:43,826 INFO    HandlerThread:2017346 [interfaces.py:finish():202] Joined gpu monitor
2023-12-25 08:34:43,826 INFO    HandlerThread:2017346 [interfaces.py:finish():202] Joined memory monitor
2023-12-25 08:34:43,826 INFO    HandlerThread:2017346 [interfaces.py:finish():202] Joined network monitor
2023-12-25 08:34:52,653 INFO    SenderThread:2017346 [sender.py:finish():1548] shutting down sender
2023-12-25 08:34:52,653 INFO    SenderThread:2017346 [dir_watcher.py:finish():358] shutting down directory watcher
2023-12-25 08:34:53,528 INFO    SenderThread:2017346 [dir_watcher.py:finish():388] scan: /alpha/overcooked_rl/algorithms/baselines/wandb/run-20231225_083257-84x3ne8d/files
2023-12-25 08:34:53,528 INFO    SenderThread:2017346 [dir_watcher.py:finish():402] scan save: /alpha/overcooked_rl/algorithms/baselines/wandb/run-20231225_083257-84x3ne8d/files/conda-environment.yaml conda-environment.yaml
2023-12-25 08:34:53,528 INFO    SenderThread:2017346 [dir_watcher.py:finish():402] scan save: /alpha/overcooked_rl/algorithms/baselines/wandb/run-20231225_083257-84x3ne8d/files/config.yaml config.yaml
2023-12-25 08:34:53,529 INFO    SenderThread:2017346 [dir_watcher.py:finish():402] scan save: /alpha/overcooked_rl/algorithms/baselines/wandb/run-20231225_083257-84x3ne8d/files/requirements.txt requirements.txt
2023-12-25 08:34:53,531 INFO    SenderThread:2017346 [dir_watcher.py:finish():402] scan save: /alpha/overcooked_rl/algorithms/baselines/wandb/run-20231225_083257-84x3ne8d/files/wandb-metadata.json wandb-metadata.json
2023-12-25 08:34:53,531 INFO    SenderThread:2017346 [file_pusher.py:finish():175] shutting down file pusher
2023-12-25 08:34:53,531 INFO    SenderThread:2017346 [file_pusher.py:join():181] waiting for file pusher
2023-12-25 08:34:54,304 INFO    wandb-upload_1:2017346 [upload_job.py:push():131] Uploaded file /alpha/overcooked_rl/algorithms/baselines/wandb/run-20231225_083257-84x3ne8d/files/config.yaml
2023-12-25 08:34:58,042 WARNING FileStreamThread:2017346 [file_stream.py:request_with_retry():673] requests_with_retry encountered retryable exception: HTTPSConnectionPool(host='api.wandb.ai', port=443): Max retries exceeded with url: /files/wanghm/overcooked_rl/84x3ne8d/file_stream (Caused by SSLError(SSLError(1, '[SSL: KRB5_S_TKT_NYV] unexpected eof while reading (_ssl.c:2570)'))). func: functools.partial(<bound method Session.post of <requests.sessions.Session object at 0x7f9372ef1a10>>, timeout=180), args: ('https://api.wandb.ai/files/wanghm/overcooked_rl/84x3ne8d/file_stream',), kwargs: {'json': {'complete': False, 'failed': False, 'dropped': 0, 'uploaded': ['wandb-metadata.json']}}
2023-12-25 08:35:02,680 INFO    wandb-upload_0:2017346 [upload_job.py:push():131] Uploaded file /alpha/overcooked_rl/algorithms/baselines/wandb/run-20231225_083257-84x3ne8d/files/conda-environment.yaml
2023-12-25 08:35:57,045 INFO    wandb-upload_3:2017346 [retry.py:__call__():172] Retry attempt failed:
Traceback (most recent call last):
  File "/home/wanghm/anaconda3/envs/overcooked_ai/lib/python3.7/site-packages/urllib3/connection.py", line 160, in _new_conn
    (self._dns_host, self.port), self.timeout, **extra_kw
  File "/home/wanghm/anaconda3/envs/overcooked_ai/lib/python3.7/site-packages/urllib3/util/connection.py", line 84, in create_connection
    raise err
  File "/home/wanghm/anaconda3/envs/overcooked_ai/lib/python3.7/site-packages/urllib3/util/connection.py", line 74, in create_connection
    sock.connect(sa)
socket.timeout: timed out

During handling of the above exception, another exception occurred:

Traceback (most recent call last):
  File "/home/wanghm/anaconda3/envs/overcooked_ai/lib/python3.7/site-packages/urllib3/connectionpool.py", line 677, in urlopen
    chunked=chunked,
  File "/home/wanghm/anaconda3/envs/overcooked_ai/lib/python3.7/site-packages/urllib3/connectionpool.py", line 381, in _make_request
    self._validate_conn(conn)
  File "/home/wanghm/anaconda3/envs/overcooked_ai/lib/python3.7/site-packages/urllib3/connectionpool.py", line 978, in _validate_conn
    conn.connect()
  File "/home/wanghm/anaconda3/envs/overcooked_ai/lib/python3.7/site-packages/urllib3/connection.py", line 309, in connect
    conn = self._new_conn()
  File "/home/wanghm/anaconda3/envs/overcooked_ai/lib/python3.7/site-packages/urllib3/connection.py", line 167, in _new_conn
    % (self.host, self.timeout),
urllib3.exceptions.ConnectTimeoutError: (<urllib3.connection.HTTPSConnection object at 0x7f934824cd90>, 'Connection to api.wandb.ai timed out. (connect timeout=20)')

During handling of the above exception, another exception occurred:

Traceback (most recent call last):
  File "/home/wanghm/anaconda3/envs/overcooked_ai/lib/python3.7/site-packages/requests/adapters.py", line 449, in send
    timeout=timeout
  File "/home/wanghm/anaconda3/envs/overcooked_ai/lib/python3.7/site-packages/urllib3/connectionpool.py", line 727, in urlopen
    method, url, error=e, _pool=self, _stacktrace=sys.exc_info()[2]
  File "/home/wanghm/anaconda3/envs/overcooked_ai/lib/python3.7/site-packages/urllib3/util/retry.py", line 446, in increment
    raise MaxRetryError(_pool, url, error or ResponseError(cause))
urllib3.exceptions.MaxRetryError: HTTPSConnectionPool(host='api.wandb.ai', port=443): Max retries exceeded with url: /graphql (Caused by ConnectTimeoutError(<urllib3.connection.HTTPSConnection object at 0x7f934824cd90>, 'Connection to api.wandb.ai timed out. (connect timeout=20)'))

During handling of the above exception, another exception occurred:

Traceback (most recent call last):
  File "/home/wanghm/anaconda3/envs/overcooked_ai/lib/python3.7/site-packages/wandb/sdk/lib/retry.py", line 131, in __call__
    result = self._call_fn(*args, **kwargs)
  File "/home/wanghm/anaconda3/envs/overcooked_ai/lib/python3.7/site-packages/wandb/sdk/internal/internal_api.py", line 369, in execute
    return self.client.execute(*args, **kwargs)  # type: ignore
  File "/home/wanghm/anaconda3/envs/overcooked_ai/lib/python3.7/site-packages/wandb/vendor/gql-0.2.0/wandb_gql/client.py", line 52, in execute
    result = self._get_result(document, *args, **kwargs)
  File "/home/wanghm/anaconda3/envs/overcooked_ai/lib/python3.7/site-packages/wandb/vendor/gql-0.2.0/wandb_gql/client.py", line 60, in _get_result
    return self.transport.execute(document, *args, **kwargs)
  File "/home/wanghm/anaconda3/envs/overcooked_ai/lib/python3.7/site-packages/wandb/sdk/lib/gql_request.py", line 58, in execute
    request = self.session.post(self.url, **post_args)
  File "/home/wanghm/anaconda3/envs/overcooked_ai/lib/python3.7/site-packages/requests/sessions.py", line 578, in post
    return self.request('POST', url, data=data, json=json, **kwargs)
  File "/home/wanghm/anaconda3/envs/overcooked_ai/lib/python3.7/site-packages/requests/sessions.py", line 530, in request
    resp = self.send(prep, **send_kwargs)
  File "/home/wanghm/anaconda3/envs/overcooked_ai/lib/python3.7/site-packages/requests/sessions.py", line 643, in send
    r = adapter.send(request, **kwargs)
  File "/home/wanghm/anaconda3/envs/overcooked_ai/lib/python3.7/site-packages/requests/adapters.py", line 504, in send
    raise ConnectTimeout(e, request=request)
requests.exceptions.ConnectTimeout: HTTPSConnectionPool(host='api.wandb.ai', port=443): Max retries exceeded with url: /graphql (Caused by ConnectTimeoutError(<urllib3.connection.HTTPSConnection object at 0x7f934824cd90>, 'Connection to api.wandb.ai timed out. (connect timeout=20)'))
2023-12-25 08:35:57,046 ERROR   Thread-11 :2017346 [step_upload.py:_handle_event():201] Failed to upload file: /alpha/overcooked_rl/algorithms/baselines/wandb/run-20231225_083257-84x3ne8d/files/requirements.txt
Traceback (most recent call last):
  File "/home/wanghm/anaconda3/envs/overcooked_ai/lib/python3.7/site-packages/urllib3/connection.py", line 160, in _new_conn
    (self._dns_host, self.port), self.timeout, **extra_kw
  File "/home/wanghm/anaconda3/envs/overcooked_ai/lib/python3.7/site-packages/urllib3/util/connection.py", line 84, in create_connection
    raise err
  File "/home/wanghm/anaconda3/envs/overcooked_ai/lib/python3.7/site-packages/urllib3/util/connection.py", line 74, in create_connection
    sock.connect(sa)
socket.timeout: timed out

During handling of the above exception, another exception occurred:

Traceback (most recent call last):
  File "/home/wanghm/anaconda3/envs/overcooked_ai/lib/python3.7/site-packages/urllib3/connectionpool.py", line 677, in urlopen
    chunked=chunked,
  File "/home/wanghm/anaconda3/envs/overcooked_ai/lib/python3.7/site-packages/urllib3/connectionpool.py", line 381, in _make_request
    self._validate_conn(conn)
  File "/home/wanghm/anaconda3/envs/overcooked_ai/lib/python3.7/site-packages/urllib3/connectionpool.py", line 978, in _validate_conn
    conn.connect()
  File "/home/wanghm/anaconda3/envs/overcooked_ai/lib/python3.7/site-packages/urllib3/connection.py", line 309, in connect
    conn = self._new_conn()
  File "/home/wanghm/anaconda3/envs/overcooked_ai/lib/python3.7/site-packages/urllib3/connection.py", line 167, in _new_conn
    % (self.host, self.timeout),
urllib3.exceptions.ConnectTimeoutError: (<urllib3.connection.HTTPSConnection object at 0x7f934824cd90>, 'Connection to api.wandb.ai timed out. (connect timeout=20)')

During handling of the above exception, another exception occurred:

Traceback (most recent call last):
  File "/home/wanghm/anaconda3/envs/overcooked_ai/lib/python3.7/site-packages/requests/adapters.py", line 449, in send
    timeout=timeout
  File "/home/wanghm/anaconda3/envs/overcooked_ai/lib/python3.7/site-packages/urllib3/connectionpool.py", line 727, in urlopen
    method, url, error=e, _pool=self, _stacktrace=sys.exc_info()[2]
  File "/home/wanghm/anaconda3/envs/overcooked_ai/lib/python3.7/site-packages/urllib3/util/retry.py", line 446, in increment
    raise MaxRetryError(_pool, url, error or ResponseError(cause))
urllib3.exceptions.MaxRetryError: HTTPSConnectionPool(host='api.wandb.ai', port=443): Max retries exceeded with url: /graphql (Caused by ConnectTimeoutError(<urllib3.connection.HTTPSConnection object at 0x7f934824cd90>, 'Connection to api.wandb.ai timed out. (connect timeout=20)'))

During handling of the above exception, another exception occurred:

Traceback (most recent call last):
  File "/home/wanghm/anaconda3/envs/overcooked_ai/lib/python3.7/site-packages/wandb/sdk/lib/retry.py", line 131, in __call__
    result = self._call_fn(*args, **kwargs)
  File "/home/wanghm/anaconda3/envs/overcooked_ai/lib/python3.7/site-packages/wandb/sdk/internal/internal_api.py", line 369, in execute
    return self.client.execute(*args, **kwargs)  # type: ignore
  File "/home/wanghm/anaconda3/envs/overcooked_ai/lib/python3.7/site-packages/wandb/vendor/gql-0.2.0/wandb_gql/client.py", line 52, in execute
    result = self._get_result(document, *args, **kwargs)
  File "/home/wanghm/anaconda3/envs/overcooked_ai/lib/python3.7/site-packages/wandb/vendor/gql-0.2.0/wandb_gql/client.py", line 60, in _get_result
    return self.transport.execute(document, *args, **kwargs)
  File "/home/wanghm/anaconda3/envs/overcooked_ai/lib/python3.7/site-packages/wandb/sdk/lib/gql_request.py", line 58, in execute
    request = self.session.post(self.url, **post_args)
  File "/home/wanghm/anaconda3/envs/overcooked_ai/lib/python3.7/site-packages/requests/sessions.py", line 578, in post
    return self.request('POST', url, data=data, json=json, **kwargs)
  File "/home/wanghm/anaconda3/envs/overcooked_ai/lib/python3.7/site-packages/requests/sessions.py", line 530, in request
    resp = self.send(prep, **send_kwargs)
  File "/home/wanghm/anaconda3/envs/overcooked_ai/lib/python3.7/site-packages/requests/sessions.py", line 643, in send
    r = adapter.send(request, **kwargs)
  File "/home/wanghm/anaconda3/envs/overcooked_ai/lib/python3.7/site-packages/requests/adapters.py", line 504, in send
    raise ConnectTimeout(e, request=request)
requests.exceptions.ConnectTimeout: HTTPSConnectionPool(host='api.wandb.ai', port=443): Max retries exceeded with url: /graphql (Caused by ConnectTimeoutError(<urllib3.connection.HTTPSConnection object at 0x7f934824cd90>, 'Connection to api.wandb.ai timed out. (connect timeout=20)'))

During handling of the above exception, another exception occurred:

Traceback (most recent call last):
  File "/home/wanghm/anaconda3/envs/overcooked_ai/lib/python3.7/site-packages/wandb/apis/normalize.py", line 41, in wrapper
    return func(*args, **kwargs)
  File "/home/wanghm/anaconda3/envs/overcooked_ai/lib/python3.7/site-packages/wandb/sdk/internal/internal_api.py", line 2386, in upload_urls
    "files": [file for file in files],
  File "/home/wanghm/anaconda3/envs/overcooked_ai/lib/python3.7/site-packages/wandb/sdk/internal/internal_api.py", line 344, in gql
    **kwargs,
  File "/home/wanghm/anaconda3/envs/overcooked_ai/lib/python3.7/site-packages/wandb/sdk/lib/retry.py", line 185, in __call__
    self._error_prefix, e.__class__.__name__
  File "/home/wanghm/anaconda3/envs/overcooked_ai/lib/python3.7/site-packages/wandb/errors/term.py", line 44, in termlog
    silent=not _show_info,
  File "/home/wanghm/anaconda3/envs/overcooked_ai/lib/python3.7/site-packages/wandb/errors/term.py", line 95, in _log
    click.echo(line, file=sys.stderr, nl=newline)
  File "/home/wanghm/anaconda3/envs/overcooked_ai/lib/python3.7/site-packages/click/utils.py", line 318, in echo
    file.write(out)  # type: ignore
BrokenPipeError: [Errno 32] Broken pipe

During handling of the above exception, another exception occurred:

Traceback (most recent call last):
  File "/home/wanghm/anaconda3/envs/overcooked_ai/lib/python3.7/concurrent/futures/thread.py", line 57, in run
    result = self.fn(*self.args, **self.kwargs)
  File "/home/wanghm/anaconda3/envs/overcooked_ai/lib/python3.7/site-packages/wandb/filesync/step_upload.py", line 288, in run_and_notify
    self._do_upload_sync(event)
  File "/home/wanghm/anaconda3/envs/overcooked_ai/lib/python3.7/site-packages/wandb/filesync/step_upload.py", line 330, in _do_upload_sync
    job.run()
  File "/home/wanghm/anaconda3/envs/overcooked_ai/lib/python3.7/site-packages/wandb/filesync/upload_job.py", line 57, in run
    self.push()
  File "/home/wanghm/anaconda3/envs/overcooked_ai/lib/python3.7/site-packages/wandb/filesync/upload_job.py", line 106, in push
    _, upload_headers, result = self._api.upload_urls(project, [self.save_name])
  File "/home/wanghm/anaconda3/envs/overcooked_ai/lib/python3.7/site-packages/wandb/apis/normalize.py", line 87, in wrapper
    raise CommError(message, err).with_traceback(sys.exc_info()[2])
  File "/home/wanghm/anaconda3/envs/overcooked_ai/lib/python3.7/site-packages/wandb/apis/normalize.py", line 41, in wrapper
    return func(*args, **kwargs)
  File "/home/wanghm/anaconda3/envs/overcooked_ai/lib/python3.7/site-packages/wandb/sdk/internal/internal_api.py", line 2386, in upload_urls
    "files": [file for file in files],
  File "/home/wanghm/anaconda3/envs/overcooked_ai/lib/python3.7/site-packages/wandb/sdk/internal/internal_api.py", line 344, in gql
    **kwargs,
  File "/home/wanghm/anaconda3/envs/overcooked_ai/lib/python3.7/site-packages/wandb/sdk/lib/retry.py", line 185, in __call__
    self._error_prefix, e.__class__.__name__
  File "/home/wanghm/anaconda3/envs/overcooked_ai/lib/python3.7/site-packages/wandb/errors/term.py", line 44, in termlog
    silent=not _show_info,
  File "/home/wanghm/anaconda3/envs/overcooked_ai/lib/python3.7/site-packages/wandb/errors/term.py", line 95, in _log
    click.echo(line, file=sys.stderr, nl=newline)
  File "/home/wanghm/anaconda3/envs/overcooked_ai/lib/python3.7/site-packages/click/utils.py", line 318, in echo
    file.write(out)  # type: ignore
wandb.errors.CommError: [Errno 32] Broken pipe
2023-12-25 08:35:57,598 INFO    SenderThread:2017346 [file_stream.py:finish():595] file stream finish called
2023-12-25 08:37:10,861 WARNING FileStreamThread:2017346 [file_stream.py:request_with_retry():673] requests_with_retry encountered retryable exception: HTTPSConnectionPool(host='api.wandb.ai', port=443): Max retries exceeded with url: /files/wanghm/overcooked_rl/84x3ne8d/file_stream (Caused by NewConnectionError('<urllib3.connection.HTTPSConnection object at 0x7f934824cb50>: Failed to establish a new connection: [Errno 110] Connection timed out')). func: functools.partial(<bound method Session.post of <requests.sessions.Session object at 0x7f9372ef1a10>>, timeout=180), args: ('https://api.wandb.ai/files/wanghm/overcooked_rl/84x3ne8d/file_stream',), kwargs: {'json': {'complete': False, 'failed': False, 'dropped': 0, 'uploaded': ['wandb-metadata.json']}}
2023-12-25 08:37:32,826 WARNING FileStreamThread:2017346 [file_stream.py:request_with_retry():673] requests_with_retry encountered retryable exception: HTTPSConnectionPool(host='api.wandb.ai', port=443): Max retries exceeded with url: /files/wanghm/overcooked_rl/84x3ne8d/file_stream (Caused by SSLError(SSLError(1, '[SSL: KRB5_S_TKT_NYV] unexpected eof while reading (_ssl.c:2570)'))). func: functools.partial(<bound method Session.post of <requests.sessions.Session object at 0x7f9372ef1a10>>, timeout=180), args: ('https://api.wandb.ai/files/wanghm/overcooked_rl/84x3ne8d/file_stream',), kwargs: {'json': {'complete': False, 'failed': False, 'dropped': 0, 'uploaded': ['wandb-metadata.json']}}
2023-12-25 08:37:51,445 WARNING FileStreamThread:2017346 [file_stream.py:request_with_retry():673] requests_with_retry encountered retryable exception: HTTPSConnectionPool(host='api.wandb.ai', port=443): Max retries exceeded with url: /files/wanghm/overcooked_rl/84x3ne8d/file_stream (Caused by SSLError(SSLError(1, '[SSL: KRB5_S_TKT_NYV] unexpected eof while reading (_ssl.c:2570)'))). func: functools.partial(<bound method Session.post of <requests.sessions.Session object at 0x7f9372ef1a10>>, timeout=180), args: ('https://api.wandb.ai/files/wanghm/overcooked_rl/84x3ne8d/file_stream',), kwargs: {'json': {'complete': False, 'failed': False, 'dropped': 0, 'uploaded': ['wandb-metadata.json']}}
2023-12-25 08:38:17,148 INFO    SenderThread:2017346 [file_stream.py:finish():599] file stream finish is done
