2023-12-25 08:30:24,772 INFO    MainThread:2016964 [wandb_setup.py:_flush():76] Current SDK version is 0.15.12
2023-12-25 08:30:24,772 INFO    MainThread:2016964 [wandb_setup.py:_flush():76] Configure stats pid to 2016964
2023-12-25 08:30:24,772 INFO    MainThread:2016964 [wandb_setup.py:_flush():76] Loading settings from /home/wanghm/.config/wandb/settings
2023-12-25 08:30:24,772 INFO    MainThread:2016964 [wandb_setup.py:_flush():76] Loading settings from /alpha/overcooked_rl/algorithms/baselines/wandb/settings
2023-12-25 08:30:24,772 INFO    MainThread:2016964 [wandb_setup.py:_flush():76] Loading settings from environment variables: {}
2023-12-25 08:30:24,772 INFO    MainThread:2016964 [wandb_setup.py:_flush():76] Applying setup settings: {'_disable_service': False}
2023-12-25 08:30:24,772 INFO    MainThread:2016964 [wandb_setup.py:_flush():76] Inferring run settings from compute environment: {'program_relpath': 'algorithms/baselines/sp_ppo.py', 'program_abspath': '/alpha/overcooked_rl/algorithms/baselines/sp_ppo.py', 'program': '/alpha/overcooked_rl/algorithms/baselines/sp_ppo.py'}
2023-12-25 08:30:24,772 INFO    MainThread:2016964 [wandb_init.py:_log_setup():528] Logging user logs to /alpha/overcooked_rl/algorithms/baselines/wandb/run-20231225_083024-s3ix4cgb/logs/debug.log
2023-12-25 08:30:24,772 INFO    MainThread:2016964 [wandb_init.py:_log_setup():529] Logging internal logs to /alpha/overcooked_rl/algorithms/baselines/wandb/run-20231225_083024-s3ix4cgb/logs/debug-internal.log
2023-12-25 08:30:24,772 INFO    MainThread:2016964 [wandb_init.py:init():568] calling init triggers
2023-12-25 08:30:24,772 INFO    MainThread:2016964 [wandb_init.py:init():576] wandb.init called with sweep_config: {}
config: {'hidden_dim': 128, 'batch_size': 4096, 'mini_batch_size': 128, 'use_minibatch': False, 'lr': 0.0008, 'gamma': 0.99, 'epsilon': 0.05, 'use_state_norm': False, 'use_reward_scaling': True, 'entropy_coef': 0.01, 'device': 'cpu', 'layout': 'soup_coordination', 'num_episodes': 2000, 'seed': 0, 'use_wandb': True, 'max_episode_steps': 600, 'state_dim': 96, 'action_dim': 6}
2023-12-25 08:30:24,772 INFO    MainThread:2016964 [wandb_init.py:init():618] starting backend
2023-12-25 08:30:24,772 INFO    MainThread:2016964 [wandb_init.py:init():622] setting up manager
2023-12-25 08:30:24,774 INFO    MainThread:2016964 [backend.py:_multiprocessing_setup():107] multiprocessing start_methods=fork,spawn,forkserver, using: spawn
2023-12-25 08:30:24,775 INFO    MainThread:2016964 [wandb_init.py:init():628] backend started and connected
2023-12-25 08:30:24,779 INFO    MainThread:2016964 [wandb_init.py:init():720] updated telemetry
2023-12-25 08:30:24,795 INFO    MainThread:2016964 [wandb_init.py:init():753] communicating run to backend with 90.0 second timeout
2023-12-25 08:31:13,405 INFO    Thread-1  :2016964 [retry.py:__call__():172] Retry attempt failed:
Traceback (most recent call last):
  File "/home/wanghm/anaconda3/envs/overcooked_ai/lib/python3.7/site-packages/urllib3/connection.py", line 160, in _new_conn
    (self._dns_host, self.port), self.timeout, **extra_kw
  File "/home/wanghm/anaconda3/envs/overcooked_ai/lib/python3.7/site-packages/urllib3/util/connection.py", line 84, in create_connection
    raise err
  File "/home/wanghm/anaconda3/envs/overcooked_ai/lib/python3.7/site-packages/urllib3/util/connection.py", line 74, in create_connection
    sock.connect(sa)
socket.timeout: timed out

During handling of the above exception, another exception occurred:

Traceback (most recent call last):
  File "/home/wanghm/anaconda3/envs/overcooked_ai/lib/python3.7/site-packages/urllib3/connectionpool.py", line 677, in urlopen
    chunked=chunked,
  File "/home/wanghm/anaconda3/envs/overcooked_ai/lib/python3.7/site-packages/urllib3/connectionpool.py", line 381, in _make_request
    self._validate_conn(conn)
  File "/home/wanghm/anaconda3/envs/overcooked_ai/lib/python3.7/site-packages/urllib3/connectionpool.py", line 978, in _validate_conn
    conn.connect()
  File "/home/wanghm/anaconda3/envs/overcooked_ai/lib/python3.7/site-packages/urllib3/connection.py", line 309, in connect
    conn = self._new_conn()
  File "/home/wanghm/anaconda3/envs/overcooked_ai/lib/python3.7/site-packages/urllib3/connection.py", line 167, in _new_conn
    % (self.host, self.timeout),
urllib3.exceptions.ConnectTimeoutError: (<urllib3.connection.HTTPSConnection object at 0x7f01daeb97d0>, 'Connection to api.wandb.ai timed out. (connect timeout=20)')

During handling of the above exception, another exception occurred:

Traceback (most recent call last):
  File "/home/wanghm/anaconda3/envs/overcooked_ai/lib/python3.7/site-packages/requests/adapters.py", line 449, in send
    timeout=timeout
  File "/home/wanghm/anaconda3/envs/overcooked_ai/lib/python3.7/site-packages/urllib3/connectionpool.py", line 727, in urlopen
    method, url, error=e, _pool=self, _stacktrace=sys.exc_info()[2]
  File "/home/wanghm/anaconda3/envs/overcooked_ai/lib/python3.7/site-packages/urllib3/util/retry.py", line 446, in increment
    raise MaxRetryError(_pool, url, error or ResponseError(cause))
urllib3.exceptions.MaxRetryError: HTTPSConnectionPool(host='api.wandb.ai', port=443): Max retries exceeded with url: /graphql (Caused by ConnectTimeoutError(<urllib3.connection.HTTPSConnection object at 0x7f01daeb97d0>, 'Connection to api.wandb.ai timed out. (connect timeout=20)'))

During handling of the above exception, another exception occurred:

Traceback (most recent call last):
  File "/home/wanghm/anaconda3/envs/overcooked_ai/lib/python3.7/site-packages/wandb/sdk/lib/retry.py", line 131, in __call__
    result = self._call_fn(*args, **kwargs)
  File "/home/wanghm/anaconda3/envs/overcooked_ai/lib/python3.7/site-packages/wandb/sdk/internal/internal_api.py", line 366, in execute
    return self.client.execute(*args, **kwargs)  # type: ignore
  File "/home/wanghm/anaconda3/envs/overcooked_ai/lib/python3.7/site-packages/wandb/vendor/gql-0.2.0/wandb_gql/client.py", line 52, in execute
    result = self._get_result(document, *args, **kwargs)
  File "/home/wanghm/anaconda3/envs/overcooked_ai/lib/python3.7/site-packages/wandb/vendor/gql-0.2.0/wandb_gql/client.py", line 60, in _get_result
    return self.transport.execute(document, *args, **kwargs)
  File "/home/wanghm/anaconda3/envs/overcooked_ai/lib/python3.7/site-packages/wandb/sdk/lib/gql_request.py", line 58, in execute
    request = self.session.post(self.url, **post_args)
  File "/home/wanghm/anaconda3/envs/overcooked_ai/lib/python3.7/site-packages/requests/sessions.py", line 578, in post
    return self.request('POST', url, data=data, json=json, **kwargs)
  File "/home/wanghm/anaconda3/envs/overcooked_ai/lib/python3.7/site-packages/requests/sessions.py", line 530, in request
    resp = self.send(prep, **send_kwargs)
  File "/home/wanghm/anaconda3/envs/overcooked_ai/lib/python3.7/site-packages/requests/sessions.py", line 643, in send
    r = adapter.send(request, **kwargs)
  File "/home/wanghm/anaconda3/envs/overcooked_ai/lib/python3.7/site-packages/requests/adapters.py", line 504, in send
    raise ConnectTimeout(e, request=request)
requests.exceptions.ConnectTimeout: HTTPSConnectionPool(host='api.wandb.ai', port=443): Max retries exceeded with url: /graphql (Caused by ConnectTimeoutError(<urllib3.connection.HTTPSConnection object at 0x7f01daeb97d0>, 'Connection to api.wandb.ai timed out. (connect timeout=20)'))
2023-12-25 08:31:54,824 ERROR   MainThread:2016964 [wandb_init.py:init():779] encountered error: Run initialization has timed out after 90.0 sec. 
Please refer to the documentation for additional information: https://docs.wandb.ai/guides/track/tracking-faq#initstarterror-error-communicating-with-wandb-process-
2023-12-25 08:31:56,828 ERROR   MainThread:2016964 [wandb_init.py:init():1188] Run initialization has timed out after 90.0 sec. 
Please refer to the documentation for additional information: https://docs.wandb.ai/guides/track/tracking-faq#initstarterror-error-communicating-with-wandb-process-
Traceback (most recent call last):
  File "/home/wanghm/anaconda3/envs/overcooked_ai/lib/python3.7/site-packages/wandb/sdk/wandb_init.py", line 1170, in init
    run = wi.init()
  File "/home/wanghm/anaconda3/envs/overcooked_ai/lib/python3.7/site-packages/wandb/sdk/wandb_init.py", line 785, in init
    raise error
wandb.errors.CommError: Run initialization has timed out after 90.0 sec. 
Please refer to the documentation for additional information: https://docs.wandb.ai/guides/track/tracking-faq#initstarterror-error-communicating-with-wandb-process-
2023-12-25 08:31:59,827 WARNING MsgRouterThr:2016964 [router.py:message_loop():77] message_loop has been closed
